Workbook

Sheet Summary
A1: Mapping the Shrines of Pakistan: costed expansion, December 2026 to December 2027
A2: Prepared by Rauf Nawaz for discussion with Professor Teren Sevea, 13 October 2026. Estimates, not quotations; every figure traces to the Assumptions sheet.
A4: Exchange rate (PKR per USD) | B4: =Assumptions!$C$5 -> 277
A6: Category | B6: Tier 1 adds (USD) | C6: Tier 2 adds (USD) | D6: Tier 3 adds (USD) | E6: Tier 1 total (USD) | F6: Tier 2 cumulative (USD) | G6: Tier 3 cumulative (USD) | H6: Tier 3 cumulative (PKR)
A7: Fieldwork teams and travel | B7: =SUMIFS('Line Items'!$G$5:$G$210,'Line Items'!$A$5:$A$210,1,'Line Items'!$B$5:$B$210,$A7) -> 1792.491 | C7: =SUMIFS('Line Items'!$G$5:$G$210,'Line Items'!$A$5:$A$210,2,'Line Items'!$B$5:$B$210,$A7) -> 5519.8195 | D7: =SUMIFS('Line Items'!$G$5:$G$210,'Line Items'!$A$5:$A$210,3,'Line Items'!$B$5:$B$210,$A7) -> 3810.0397 | E7: =B7 -> 1792.491 | F7: =B7+C7 -> 7312.3105 | G7: =B7+C7+D7 -> 11122.35 | H7: =G7*$B$4 -> 3080891
A8: Interviews | B8: =SUMIFS('Line Items'!$G$5:$G$210,'Line Items'!$A$5:$A$210,1,'Line Items'!$B$5:$B$210,$A8) -> 1121.9458 | C8: =SUMIFS('Line Items'!$G$5:$G$210,'Line Items'!$A$5:$A$210,2,'Line Items'!$B$5:$B$210,$A8) -> 997.2852 | D8: =SUMIFS('Line Items'!$G$5:$G$210,'Line Items'!$A$5:$A$210,3,'Line Items'!$B$5:$B$210,$A8) -> 685.63357 | E8: =B8 -> 1121.9458 | F8: =B8+C8 -> 2119.231 | G8: =B8+C8+D8 -> 2804.8646 | H8: =G8*$B$4 -> 776947.5
A9: Data and coding | B9: =SUMIFS('Line Items'!$G$5:$G$210,'Line Items'!$A$5:$A$210,1,'Line Items'!$B$5:$B$210,$A9) -> 270 | C9: =SUMIFS('Line Items'!$G$5:$G$210,'Line Items'!$A$5:$A$210,2,'Line Items'!$B$5:$B$210,$A9) -> 240 | D9: =SUMIFS('Line Items'!$G$5:$G$210,'Line Items'!$A$5:$A$210,3,'Line Items'!$B$5:$B$210,$A9) -> 165 | E9: =B9 -> 270 | F9: =B9+C9 -> 510 | G9: =B9+C9+D9 -> 675 | H9: =G9*$B$4 -> 186975
A10: Principal investigator travel | B10: =SUMIFS('Line Items'!$G$5:$G$210,'Line Items'!$A$5:$A$210,1,'Line Items'!$B$5:$B$210,$A10) -> 1450 | C10: =SUMIFS('Line Items'!$G$5:$G$210,'Line Items'!$A$5:$A$210,2,'Line Items'!$B$5:$B$210,$A10) -> 2147.5 | D10: =SUMIFS('Line Items'!$G$5:$G$210,'Line Items'!$A$5:$A$210,3,'Line Items'!$B$5:$B$210,$A10) -> 765 | E10: =B10 -> 1450 | F10: =B10+C10 -> 3597.5 | G10: =B10+C10+D10 -> 4362.5 | H10: =G10*$B$4 -> 1208412.5
A11: Urs and qawwali recording | B11: =SUMIFS('Line Items'!$G$5:$G$210,'Line Items'!$A$5:$A$210,1,'Line Items'!$B$5:$B$210,$A11) -> 726.30325 | C11: =SUMIFS('Line Items'!$G$5:$G$210,'Line Items'!$A$5:$A$210,2,'Line Items'!$B$5:$B$210,$A11) -> 968.40433 | D11: =SUMIFS('Line Items'!$G$5:$G$210,'Line Items'!$A$5:$A$210,3,'Line Items'!$B$5:$B$210,$A11) -> 726.30325 | E11: =B11 -> 726.30325 | F11: =B11+C11 -> 1694.7076 | G11: =B11+C11+D11 -> 2421.0108 | H11: =G11*$B$4 -> 670620
A12: Oral histories | B12: =SUMIFS('Line Items'!$G$5:$G$210,'Line Items'!$A$5:$A$210,1,'Line Items'!$B$5:$B$210,$A12) -> 180 | C12: =SUMIFS('Line Items'!$G$5:$G$210,'Line Items'!$A$5:$A$210,2,'Line Items'!$B$5:$B$210,$A12) -> 180 | D12: =SUMIFS('Line Items'!$G$5:$G$210,'Line Items'!$A$5:$A$210,3,'Line Items'!$B$5:$B$210,$A12) -> 144 | E12: =B12 -> 180 | F12: =B12+C12 -> 360 | G12: =B12+C12+D12 -> 504 | H12: =G12*$B$4 -> 139608
A13: Digitisation of books | B13: =SUMIFS('Line Items'!$G$5:$G$210,'Line Items'!$A$5:$A$210,1,'Line Items'!$B$5:$B$210,$A13) -> 508.5 | C13: =SUMIFS('Line Items'!$G$5:$G$210,'Line Items'!$A$5:$A$210,2,'Line Items'!$B$5:$B$210,$A13) -> 1017 | D13: =SUMIFS('Line Items'!$G$5:$G$210,'Line Items'!$A$5:$A$210,3,'Line Items'!$B$5:$B$210,$A13) -> 1017 | E13: =B13 -> 508.5 | F13: =B13+C13 -> 1525.5 | G13: =B13+C13+D13 -> 2542.5 | H13: =G13*$B$4 -> 704272.5
A14: Equipment | B14: =SUMIFS('Line Items'!$G$5:$G$210,'Line Items'!$A$5:$A$210,1,'Line Items'!$B$5:$B$210,$A14) -> 1363.4296 | C14: =SUMIFS('Line Items'!$G$5:$G$210,'Line Items'!$A$5:$A$210,2,'Line Items'!$B$5:$B$210,$A14) -> 490 | D14: =SUMIFS('Line Items'!$G$5:$G$210,'Line Items'!$A$5:$A$210,3,'Line Items'!$B$5:$B$210,$A14) -> 1100 | E14: =B14 -> 1363.4296 | F14: =B14+C14 -> 1853.4296 | G14: =B14+C14+D14 -> 2953.4296 | H14: =G14*$B$4 -> 818100
A15: Running costs | B15: =SUMIFS('Line Items'!$G$5:$G$210,'Line Items'!$A$5:$A$210,1,'Line Items'!$B$5:$B$210,$A15) -> 170 | C15: =SUMIFS('Line Items'!$G$5:$G$210,'Line Items'!$A$5:$A$210,2,'Line Items'!$B$5:$B$210,$A15) -> 200 | D15: =SUMIFS('Line Items'!$G$5:$G$210,'Line Items'!$A$5:$A$210,3,'Line Items'!$B$5:$B$210,$A15) -> 320 | E15: =B15 -> 170 | F15: =B15+C15 -> 370 | G15: =B15+C15+D15 -> 690 | H15: =G15*$B$4 -> 191130
A16: Dissemination | B16: =SUMIFS('Line Items'!$G$5:$G$210,'Line Items'!$A$5:$A$210,1,'Line Items'!$B$5:$B$210,$A16) -> 0 | C16: =SUMIFS('Line Items'!$G$5:$G$210,'Line Items'!$A$5:$A$210,2,'Line Items'!$B$5:$B$210,$A16) -> 250 | D16: =SUMIFS('Line Items'!$G$5:$G$210,'Line Items'!$A$5:$A$210,3,'Line Items'!$B$5:$B$210,$A16) -> 250 | E16: =B16 -> 0 | F16: =B16+C16 -> 250 | G16: =B16+C16+D16 -> 500 | H16: =G16*$B$4 -> 138500
A17: Subtotal | B17: =SUM(B7:B16) -> 7582.6697 | C17: =SUM(C7:C16) -> 12010.009 | D17: =SUM(D7:D16) -> 8982.9765 | E17: =SUM(E7:E16) -> 7582.6697 | F17: =SUM(F7:F16) -> 19592.679 | G17: =SUM(G7:G16) -> 28575.655 | H17: =SUM(H7:H16) -> 7915456.5
A18: Contingency | B18: =B17*Assumptions!$C$6 -> 758.26697 | C18: =C17*Assumptions!$C$6 -> 1201.0009 | D18: =D17*Assumptions!$C$6 -> 898.29765 | E18: =E17*Assumptions!$C$6 -> 758.26697 | F18: =F17*Assumptions!$C$6 -> 1959.2679 | G18: =G17*Assumptions!$C$6 -> 2857.5655 | H18: =H17*Assumptions!$C$6 -> 791545.65
A19: Total | B19: =B17+B18 -> 8340.9366 | C19: =C17+C18 -> 13211.01 | D19: =D17+D18 -> 9881.2742 | E19: =E17+E18 -> 8340.9366 | F19: =F17+F18 -> 21551.947 | G19: =G17+G18 -> 31433.221 | H19: =H17+H18 -> 8707002.2
A21: Scale and unit cost
A22: Shrines coded (cumulative) | E22: =SUMIFS(Regions!$C$5:$C$17,Regions!$A$5:$A$17,"<="&1) -> 36 | F22: =SUMIFS(Regions!$C$5:$C$17,Regions!$A$5:$A$17,"<="&2) -> 68 | G22: =SUMIFS(Regions!$C$5:$C$17,Regions!$A$5:$A$17,"<="&3) -> 90
A23: Total cost per shrine coded (all costs) | E23: =E19/E22 -> 231.69268 | F23: =F19/F22 -> 316.94039 | G23: =G19/G22 -> 349.25801
A24: Books digitised (cumulative) | E24: =SUMIFS('Line Items'!$D$5:$D$210,'Line Items'!$A$5:$A$210,"<="&1,'Line Items'!$C$5:$C$210,"Books digitised*") -> 30 | F24: =SUMIFS('Line Items'!$D$5:$D$210,'Line Items'!$A$5:$A$210,"<="&2,'Line Items'!$C$5:$C$210,"Books digitised*") -> 90 | G24: =SUMIFS('Line Items'!$D$5:$D$210,'Line Items'!$A$5:$A$210,"<="&3,'Line Items'!$C$5:$C$210,"Books digitised*") -> 150
A25: Urs and qawwali events recorded (cumulative) | E25: =SUMIFS('Line Items'!$D$5:$D$210,'Line Items'!$A$5:$A$210,"<="&1,'Line Items'!$C$5:$C$210,"Events recorded*") -> 3 | F25: =SUMIFS('Line Items'!$D$5:$D$210,'Line Items'!$A$5:$A$210,"<="&2,'Line Items'!$C$5:$C$210,"Events recorded*") -> 7 | G25: =SUMIFS('Line Items'!$D$5:$D$210,'Line Items'!$A$5:$A$210,"<="&3,'Line Items'!$C$5:$C$210,"Events recorded*") -> 10
A26: Interviews (cumulative) | E26: =E22*Assumptions!$C$13 -> 180 | F26: =F22*Assumptions!$C$13 -> 340 | G26: =G22*Assumptions!$C$13 -> 450
A28: Funding already requested
A29: Mittal Institute Winter Session Grant (pending, due 15 October 2026) | E29: 2950
A30: Tier 1 balance still to raise | E30: =E19-E29 -> 5390.9366
A31: Tiers 2 and 3 to raise | F31: =C19 -> 13211.01 | G31: =D19 -> 9881.2742
A33: Tier 1, Lahore and Pakpattan core: the 36 shrine winter sample in the Mittal proposal, carried through the year with oral histories, three urs recordings and the first 30 books digitised.
A34: Tier 2, Punjab expansion (summer 2027): Multan, Uch Sharif and Bahawalpur, Jhang, Okara, Kasur, Taunsa and Dera Ghazi Khan; two teams in parallel; 60 more books.
A35: Tier 3, beyond Punjab (autumn 2027): Karachi, Thatta, Sehwan, Hyderabad and Bhit Shah in Sindh, Islamabad and Rawalpindi, and Peshawar, with locally hired Sindhi and Pashto speaking enumerators.
A36: Excluded: Balochistan, for reasons of security and access; Rauf's own time, which is unpaid; lodging in Lahore, which family provides.
A37: Colour code: blue text is an input, green text links to another sheet, black text is a formula. Yellow rows on the Assumptions sheet are judgement calls to confirm.

Sheet Assumptions
A1: Assumptions and unit costs
A2: Blue cells are inputs: change them and every sheet recalculates. Yellow rows are judgement calls Rauf should confirm before the budget goes to a funder.
A4: Key | B4: Assumption | C4: Value | D4: Unit | E4: Basis and source
A5: fx | B5: Exchange rate | C5: 277 | D5: PKR per USD | E5: Rupee closed at 277.11 per USD on 30 September 2026 (ProPakistani). Revisit at submission.
A6: contingency | B6: Contingency | C6: 0.1 | D6: share of subtotal | E6: Standard allowance for fare and price movement; the rupee and fuel linked bus fares both move.
A7: enum_day | B7: Enumerator day rate | C7: 15 | D7: USD per day | E7: The project's own rate in the Mittal budget ($450 for 30 enumerator days), about PKR 4,150 a day. Punjab minimum wage is PKR 40,000 a month from 1 July 2025 (WageIndicator), about PKR 1,540 a working day, so the rate is roughly 2.7 times the minimum.
A8: coord_day | B8: Field coordinator day rate | C8: 25 | D8: USD per day | E8: Assumption: a senior enumerator who supervises outstation teams, checks forms daily and manages consent records.
A9: fem_day | B9: Female enumerator day rate | C9: 15 | D9: USD per day | E9: Same rate as other enumerators, so that the women's strand is not paid less.
A10: visits_per_shrine | B10: Observation visits per shrine | C10: 2 | D10: visits | E10: Proposal design: one weekday visit and one Thursday evening visit.
A11: visits_per_day | B11: Visits completed per team day | C11: 2.4 | D11: visits | E11: Mittal budget basis: 72 visits in 30 enumerator days.
A12: fem_days_per_shrine | B12: Female enumerator days per shrine | C12: 0.5 | D12: days | E12: Assumption: women's spaces and women devotee interviews take about half a day per shrine.
A13: interviews_per_shrine | B13: Interviews per shrine | C13: 5 | D13: interviews | E13: Proposal design: custodian or Auqaf manager, senior khadim, three devotees.
A14: devotees_per_shrine | B14: Devotee interviews per shrine | C14: 3 | D14: interviews | E14: Proposal design.
A15: interview_min | B15: Average interview length | C15: 25 | D15: minutes | E15: Assumption for a semi structured interview in Urdu or Punjabi.
A16: token_pkr | B16: Token of thanks per devotee interview | C16: 500 | D16: PKR | E16: Assumption: a small gift in kind or cash. Whether to offer one at all is an ethics question for CUHS and Rauf.
... A49: sindhi_review_days | B49: Sindhi and Pashto translation review days | C49: 10 | D49: days | E49: Assumption: a reviewer checks instrument translations and transcripts for Tier 3.

Sheet Regions
A1: Fieldwork regions by tier
A2: Shrine counts, fares and team composition are inputs (blue). Field days, nights and visits are computed.
A4: Tier | B4: Region | C4: Shrines | D4: Travelling team (people) | E4: Round trip fare per traveller (PKR) | F4: Domestic flights per traveller (one way legs) | G4: Hired car days | H4: Local hires (enumerators) | I4: Visits | J4: Team field days | K4: Enumerator days | L4: Female enumerator days | M4: Coordinator days | N4: Nights away | O4: Example shrines | P4: Notes
A5: 1 | B5: Lahore | C5: 30 | D5: 0 | E5: 0 | F5: 0 | G5: 0 | H5: 0 | I5: =C5*Assumptions!$C$10 -> 60 | J5: =ROUNDUP(I5/Assumptions!$C$11,0) -> 25 | K5: =IF(D5=0,J5,J5*2) -> 25 | L5: =C5*Assumptions!$C$12 -> 15 | M5: =IF(D5=0,0,J5) -> 0 | N5: =IF(OR(D5=0,B5="Kasur"),0,J5+1) -> 0 | O5: Data Darbar, Bibi Pak Daman, Madho Lal Hussain, Shah Jamal, Abul Muali Qadri, Wasif Ali Wasif | P5: Home city; lodging with family; Mittal winter sample.
A6: 1 | B6: Pakpattan | C6: 6 | D6: 3 | E6: 3000 | F6: 0 | G6: 0 | H6: 0 | I6: =C6*Assumptions!$C$10 -> 12 | J6: =ROUNDUP(I6/Assumptions!$C$11,0) -> 5 | K6: =IF(D6=0,J6,J6*2) -> 10 | L6: =C6*Assumptions!$C$12 -> 3 | M6: =IF(D6=0,0,J6) -> 5 | N6: =IF(OR(D6=0,B6="Kasur"),0,J6+1) -> 6 | O6: Baba Farid Ganj Shakar and five district shrines | P6: Mittal winter sample. No listed Daewoo fare; PKR 1,500 each way assumed via Okara (Okara fare PKR 890).
A7: 2 | B7: Multan | C7: 8 | D7: 3 | E7: 6860 | F7: 0 | G7: 0 | H7: 0 | I7: =C7*Assumptions!$C$10 -> 16 | J7: =ROUNDUP(I7/Assumptions!$C$11,0) -> 7 | K7: =IF(D7=0,J7,J7*2) -> 14 | L7: =C7*Assumptions!$C$12 -> 4 | M7: =IF(D7=0,0,J7) -> 7 | N7: =IF(OR(D7=0,B7="Kasur"),0,J7+1) -> 8 | O7: Bahauddin Zakariya, Shah Rukn e Alam, Shams Tabrez | P7: Daewoo Gold Lahore to Multan PKR 3,430 each way.
A8: 2 | B8: Uch Sharif and Bahawalpur | C8: 8 | D8: 3 | E8: 6160 | F8: 0 | G8: 0 | H8: 0 | I8: =C8*Assumptions!$C$10 -> 16 | J8: =ROUNDUP(I8/Assumptions!$C$11,0) -> 7 | K8: =IF(D8=0,J8,J8*2) -> 14 | L8: =C8*Assumptions!$C$12 -> 4 | M8: =IF(D8=0,0,J8) -> 7 | N8: =IF(OR(D8=0,B8="Kasur"),0,J8+1) -> 8 | O8: Jalaluddin Surkh Bukhari, Bibi Jawindi, Gilani shrines of Uch | P8: Daewoo Gold Lahore to Bahawalpur PKR 2,580 each way plus PKR 500 each way to Uch (assumed).
A9: 2 | B9: Jhang | C9: 4 | D9: 3 | E9: 3160 | F9: 0 | G9: 0 | H9: 0 | I9: =C9*Assumptions!$C$10 -> 8 | J9: =ROUNDUP(I9/Assumptions!$C$11,0) -> 4 | K9: =IF(D9=0,J9,J9*2) -> 8 | L9: =C9*Assumptions!$C$12 -> 2 | M9: =IF(D9=0,0,J9) -> 4 | N9: =IF(OR(D9=0,B9="Kasur"),0,J9+1) -> 5 | O9: Shrines of Jhang and Shorkot, including Sultan Bahu at Garh Maharaja | P9: Daewoo Lahore to Jhang PKR 1,580 each way. Rehman and Lund Thomsen's lodge is in Jhang.
A10: 2 | B10: Okara | C10: 4 | D10: 3 | E10: 1780 | F10: 0 | G10: 0 | H10: 0 | I10: =C10*Assumptions!$C$10 -> 8 | J10: =ROUNDUP(I10/Assumptions!$C$11,0) -> 4 | K10: =IF(D10=0,J10,J10*2) -> 8 | L10: =C10*Assumptions!$C$12 -> 2 | M10: =IF(D10=0,0,J10) -> 4 | N10: =IF(OR(D10=0,B10="Kasur"),0,J10+1) -> 5 | O10: District shrines of Okara and Dipalpur | P10: Daewoo Lahore to Okara PKR 890 each way.
A11: 2 | B11: Kasur | C11: 4 | D11: 2 | E11: 1200 | F11: 0 | G11: 0 | H11: 0 | I11: =C11*Assumptions!$C$10 -> 8 | J11: =ROUNDUP(I11/Assumptions!$C$11,0) -> 4 | K11: =IF(D11=0,J11,J11*2) -> 8 | L11: =C11*Assumptions!$C$12 -> 2 | M11: =IF(D11=0,0,J11) -> 4 | N11: =IF(OR(D11=0,B11="Kasur"),0,J11+1) -> 0 | O11: Bulleh Shah and district shrines | P11: Day trips from Lahore; no lodging; PKR 600 each way assumed.
A12: 2 | B12: Taunsa and Dera Ghazi Khan | C12: 4 | D12: 3 | E12: 8000 | F12: 0 | G12: 0 | H12: 0 | I12: =C12*Assumptions!$C$10 -> 8 | J12: =ROUNDUP(I12/Assumptions!$C$11,0) -> 4 | K12: =IF(D12=0,J12,J12*2) -> 8 | L12: =C12*Assumptions!$C$12 -> 2 | M12: =IF(D12=0,0,J12) -> 4 | N12: =IF(OR(D12=0,B12="Kasur"),0,J12+1) -> 5 | O12: Taunsa Sharif, Sakhi Sarwar | P12: Lahore to Multan PKR 3,430 plus Multan to Dera Ghazi Khan PKR 570, each way.
A13: 3 | B13: Sindh: Karachi and Thatta | C13: 6 | D13: 1 | E13: 0 | F13: 2 | G13: 4 | H13: 2 | I13: =C13*Assumptions!$C$10 -> 12 | J13: =ROUNDUP(I13/Assumptions!$C$11,0) -> 5 | K13: =IF(D13=0,J13,J13*2) -> 10 | L13: =C13*Assumptions!$C$12 -> 3 | M13: =IF(D13=0,0,J13) -> 5 | N13: =IF(OR(D13=0,B13="Kasur"),0,J13+1) -> 6 | O13: Abdullah Shah Ghazi, Makli necropolis shrines | P13: Coordinator flies from Lahore; Sindhi speaking enumerators hired locally.
A14: 3 | B14: Sindh: Sehwan | C14: 4 | D14: 1 | E14: 0 | F14: 0 | G14: 3 | H14: 2 | I14: =C14*Assumptions!$C$10 -> 8 | J14: =ROUNDUP(I14/Assumptions!$C$11,0) -> 4 | K14: =IF(D14=0,J14,J14*2) -> 8 | L14: =C14*Assumptions!$C$12 -> 2 | M14: =IF(D14=0,0,J14) -> 4 | N14: =IF(OR(D14=0,B14="Kasur"),0,J14+1) -> 5 | O14: Lal Shahbaz Qalandar and Sehwan shrines | P14: By hired car from Karachi or Hyderabad. Local hires.
A15: 3 | B15: Sindh: Hyderabad and Bhit Shah | C15: 4 | D15: 1 | E15: 0 | F15: 0 | G15: 3 | H15: 2 | I15: =C15*Assumptions!$C$10 -> 8 | J15: =ROUNDUP(I15/Assumptions!$C$11,0) -> 4 | K15: =IF(D15=0,J15,J15*2) -> 8 | L15: =C15*Assumptions!$C$12 -> 2 | M15: =IF(D15=0,0,J15) -> 4 | N15: =IF(OR(D15=0,B15="Kasur"),0,J15+1) -> 5 | O15: Shah Abdul Latif Bhittai, Hyderabad shrines | P15: By hired car. Local hires.
A16: 3 | B16: Islamabad and Rawalpindi | C16: 4 | D16: 3 | E16: 5960 | F16: 0 | G16: 0 | H16: 0 | I16: =C16*Assumptions!$C$10 -> 8 | J16: =ROUNDUP(I16/Assumptions!$C$11,0) -> 4 | K16: =IF(D16=0,J16,J16*2) -> 8 | L16: =C16*Assumptions!$C$12 -> 2 | M16: =IF(D16=0,0,J16) -> 4 | N16: =IF(OR(D16=0,B16="Kasur"),0,J16+1) -> 5 | O16: Bari Imam, Golra Sharif | P16: Daewoo Gold Lahore to Islamabad PKR 2,980 each way.
A17: 3 | B17: Peshawar | C17: 4 | D17: 1 | E17: 9000 | F17: 0 | G17: 0 | H17: 2 | I17: =C17*Assumptions!$C$10 -> 8 | J17: =ROUNDUP(I17/Assumptions!$C$11,0) -> 4 | K17: =IF(D17=0,J17,J17*2) -> 8 | L17: =C17*Assumptions!$C$12 -> 2 | M17: =IF(D17=0,0,J17) -> 4 | N17: =IF(OR(D17=0,B17="Kasur"),0,J17+1) -> 5 | O17: Rahman Baba and Peshawar shrines | P17: Coordinator travels; Pashto speaking enumerators hired locally. PKR 4,500 each way assumed.
B18: Total | C18: =SUM(C5:C17) -> 90
A20: Note: Kasur is costed as day trips, so it carries fares but no nights away. In Sindh and Peshawar only the coordinator travels; enumerators are hired locally so that interviews run in Sindhi and Pashto.

Sheet Line Items
A1: Line items
A2: Each tier lists only what it adds. Tiers are cumulative on the Summary sheet. Quantities and unit costs are formulas that point to the Assumptions and Regions sheets.
A4: Tier | B4: Category | C4: Item | D4: Quantity | E4: Unit | F4: Unit cost (USD) | G4: Total (USD) | H4: Total (PKR) | I4: Basis
A5: 1 | B5: Fieldwork teams and travel | C5: Lahore: enumerator days | D5: =Regions!K5 -> 25 | E5: enumerator days | F5: =Assumptions!$C$7 -> 15 | G5: =D5*F5 -> 375 | H5: =G5*Assumptions!$C$5 -> 103875 | I5: Two enumerators per visit outside Lahore; singly in Lahore, as in the Mittal budget.
A6: 1 | B6: Fieldwork teams and travel | C6: Lahore: female enumerator days | D6: =Regions!L5 -> 15 | E6: days | F6: =Assumptions!$C$9 -> 15 | G6: =D6*F6 -> 225 | H6: =G6*Assumptions!$C$5 -> 62325 | I6: Women's spaces and women devotee interviews.
A7: 1 | B7: Fieldwork teams and travel | C7: Lahore: field coordinator days | D7: =Regions!M5 -> 0 | E7: days | F7: =Assumptions!$C$8 -> 25 | G7: =D7*F7 -> 0 | H7: =G7*Assumptions!$C$5 -> 0 | I7: Supervision of outstation teams.
A8: 1 | B8: Fieldwork teams and travel | C8: Lahore: local transport | D8: =Regions!J5 -> 25 | E8: team field days | F8: =Assumptions!$C$22 -> 8 | G8: =D8*F8 -> 200 | H8: =G8*Assumptions!$C$5 -> 55400 | I8: Ride hail and rickshaw between sites.
A9: 1 | B9: Fieldwork teams and travel | C9: Lahore: lodging | D9: =ROUNDUP(Regions!D5/Assumptions!$C$20,0)*Regions!N5 -> 0 | E9: room nights | F9: =Assumptions!$C$19 -> 35 | G9: =D9*F9 -> 0 | H9: =G9*Assumptions!$C$5 -> 0 | I9: Budget hotel, twin share.
A10: 1 | B10: Fieldwork teams and travel | C10: Lahore: meals away from home | D10: =Regions!D5*Regions!N5 -> 0 | E10: traveller days | F10: =Assumptions!$C$21 -> 10 | G10: =D10*F10 -> 0 | H10: =G10*Assumptions!$C$5 -> 0 | I10: Per traveller per night away.
A11: 1 | B11: Interviews | C11: Lahore: transcription and translation | D11: =Regions!C5*Assumptions!$C$13*Assumptions!$C$15/60 -> 62.5 | E11: audio hours | F11: =Assumptions!$C$17 -> 12 | G11: =D11*F11 -> 750 | H11: =G11*Assumptions!$C$5 -> 207750 | I11: Five interviews per shrine.
A12: 1 | B12: Interviews | C12: Lahore: tokens of thanks to devotees | D12: =Regions!C5*Assumptions!$C$14 -> 90 | E12: interviews | F12: =Assumptions!$C$16/Assumptions!$C$5 -> 1.8050542 | G12: =D12*F12 -> 162.45487 | H12: =G12*Assumptions!$C$5 -> 45000 | I12: Subject to CUHS and Rauf's decision.
A13: 1 | B13: Interviews | C13: Lahore: consent forms and printing | D13: =Regions!C5*Assumptions!$C$13 -> 150 | E13: interviews | F13: =Assumptions!$C$28 -> 0.15 | G13: =D13*F13 -> 22.5 | H13: =G13*Assumptions!$C$5 -> 6232.5
A14: 1 | B14: Data and coding | C14: Lahore: data entry and coding | D14: =Regions!C5*Assumptions!$C$18 -> 15 | E14: days | F14: =Assumptions!$C$7 -> 15 | G14: =D14*F14 -> 225 | H14: =G14*Assumptions!$C$5 -> 62325 | I14: Function module entry and double check.
A15: 1 | B15: Fieldwork teams and travel | C15: Pakpattan: enumerator days | D15: =Regions!K6 -> 10 | E15: enumerator days | F15: =Assumptions!$C$7 -> 15 | G15: =D15*F15 -> 150 | H15: =G15*Assumptions!$C$5 -> 41550 | I15: Two enumerators per visit outside Lahore; singly in Lahore, as in the Mittal budget.
A16: 1 | B16: Fieldwork teams and travel | C16: Pakpattan: female enumerator days | D16: =Regions!L6 -> 3 | E16: days | F16: =Assumptions!$C$9 -> 15 | G16: =D16*F16 -> 45 | H16: =G16*Assumptions!$C$5 -> 12465 | I16: Women's spaces and women devotee interviews.
A17: 1 | B17: Fieldwork teams and travel | C17: Pakpattan: field coordinator days | D17: =Regions!M6 -> 5 | E17: days | F17: =Assumptions!$C$8 -> 25 | G17: =D17*F17 -> 125 | H17: =G17*Assumptions!$C$5 -> 34625 | I17: Supervision of outstation teams.
A18: 1 | B18: Fieldwork teams and travel | C18: Pakpattan: local transport | D18: =Regions!J6 -> 5 | E18: team field days | F18: =Assumptions!$C$22 -> 8 | G18: =D18*F18 -> 40 | H18: =G18*Assumptions!$C$5 -> 11080 | I18: Ride hail and rickshaw between sites.
A19: 1 | B19: Fieldwork teams and travel | C19: Pakpattan: intercity fares | D19: =Regions!D6 -> 3 | E19: travellers | F19: =Regions!E6/Assumptions!$C$5 -> 10.830325 | G19: =D19*F19 -> 32.490975 | H19: =G19*Assumptions!$C$5 -> 9000 | I19: Round trip bus fare per traveller; see Regions.
A20: 1 | B20: Fieldwork teams and travel | C20: Pakpattan: lodging | D20: =ROUNDUP(Regions!D6/Assumptions!$C$20,0)*Regions!N6 -> 12 | E20: room nights | F20: =Assumptions!$C$19 -> 35 | G20: =D20*F20 -> 420 | H20: =G20*Assumptions!$C$5 -> 116340 | I20: Budget hotel, twin share.
A21: 1 | B21: Fieldwork teams and travel | C21: Pakpattan: meals away from home | D21: =Regions!D6*Regions!N6 -> 18 | E21: traveller days | F21: =Assumptions!$C$21 -> 10 | G21: =D21*F21 -> 180 | H21: =G21*Assumptions!$C$5 -> 49860 | I21: Per traveller per night away.
A22: 1 | B22: Interviews | C22: Pakpattan: transcription and translation | D22: =Regions!C6*Assumptions!$C$13*Assumptions!$C$15/60 -> 12.5 | E22: audio hours | F22: =Assumptions!$C$17 -> 12 | G22: =D22*F22 -> 150 | H22: =G22*Assumptions!$C$5 -> 41550 | I22: Five interviews per shrine.
A23: 1 | B23: Interviews | C23: Pakpattan: tokens of thanks to devotees | D23: =Regions!C6*Assumptions!$C$14 -> 18 | E23: interviews | F23: =Assumptions!$C$16/Assumptions!$C$5 -> 1.8050542 | G23: =D23*F23 -> 32.490975 | H23: =G23*Assumptions!$C$5 -> 9000 | I23: Subject to CUHS and Rauf's decision.
A24: 1 | B24: Interviews | C24: Pakpattan: consent forms and printing | D24: =Regions!C6*Assumptions!$C$13 -> 30 | E24: interviews | F24: =Assumptions!$C$28 -> 0.15 | G24: =D24*F24 -> 4.5 | H24: =G24*Assumptions!$C$5 -> 1246.5
A25: 1 | B25: Data and coding | C25: Pakpattan: data entry and coding | D25: =Regions!C6*Assumptions!$C$18 -> 3 | E25: days | F25: =Assumptions!$C$7 -> 15 | G25: =D25*F25 -> 45 | H25: =G25*Assumptions!$C$5 -> 12465 | I25: Function module entry and double check.
A26: 2 | B26: Fieldwork teams and travel | C26: Multan: enumerator days | D26: =Regions!K7 -> 14 | E26: enumerator days | F26: =Assumptions!$C$7 -> 15 | G26: =D26*F26 -> 210 | H26: =G26*Assumptions!$C$5 -> 58170 | I26: Two enumerators per visit outside Lahore; singly in Lahore, as in the Mittal budget.
A27: 2 | B27: Fieldwork teams and travel | C27: Multan: female enumerator days | D27: =Regions!L7 -> 4 | E27: days | F27: =Assumptions!$C$9 -> 15 | G27: =D27*F27 -> 60 | H27: =G27*Assumptions!$C$5 -> 16620 | I27: Women's spaces and women devotee interviews.
A28: 2 | B28: Fieldwork teams and travel | C28: Multan: field coordinator days | D28: =Regions!M7 -> 7 | E28: days | F28: =Assumptions!$C$8 -> 25 | G28: =D28*F28 -> 175 | H28: =G28*Assumptions!$C$5 -> 48475 | I28: Supervision of outstation teams.
A29: 2 | B29: Fieldwork teams and travel | C29: Multan: local transport | D29: =Regions!J7 -> 7 | E29: team field days | F29: =Assumptions!$C$22 -> 8 | G29: =D29*F29 -> 56 | H29: =G29*Assumptions!$C$5 -> 15512 | I29: Ride hail and rickshaw between sites.
A30: 2 | B30: Fieldwork teams and travel | C30: Multan: intercity fares | D30: =Regions!D7 -> 3 | E30: travellers | F30: =Regions!E7/Assumptions!$C$5 -> 24.765343 | G30: =D30*F30 -> 74.296029 | H30: =G30*Assumptions!$C$5 -> 20580 | I30: Round trip bus fare per traveller; see Regions.
A31: 2 | B31: Fieldwork teams and travel | C31: Multan: lodging | D31: =ROUNDUP(Regions!D7/Assumptions!$C$20,0)*Regions!N7 -> 16 | E31: room nights | F31: =Assumptions!$C$19 -> 35 | G31: =D31*F31 -> 560 | H31: =G31*Assumptions!$C$5 -> 155120 | I31: Budget hotel, twin share.
A32: 2 | B32: Fieldwork teams and travel | C32: Multan: meals away from home | D32: =Regions!D7*Regions!N7 -> 24 | E32: traveller days | F32: =Assumptions!$C$21 -> 10 | G32: =D32*F32 -> 240 | H32: =G32*Assumptions!$C$5 -> 66480 | I32: Per traveller per night away.
A33: 2 | B33: Interviews | C33: Multan: transcription and translation | D33: =Regions!C7*Assumptions!$C$13*Assumptions!$C$15/60 -> 16.666667 | E33: audio hours | F33: =Assumptions!$C$17 -> 12 | G33: =D33*F33 -> 200 | H33: =G33*Assumptions!$C$5 -> 55400 | I33: Five interviews per shrine.
A34: 2 | B34: Interviews | C34: Multan: tokens of thanks to devotees | D34: =Regions!C7*Assumptions!$C$14 -> 24 | E34: interviews | F34: =Assumptions!$C$16/Assumptions!$C$5 -> 1.8050542 | G34: =D34*F34 -> 43.3213 | H34: =G34*Assumptions!$C$5 -> 12000 | I34: Subject to CUHS and Rauf's decision.
A35: 2 | B35: Interviews | C35: Multan: consent forms and printing | D35: =Regions!C7*Assumptions!$C$13 -> 40 | E35: interviews | F35: =Assumptions!$C$28 -> 0.15 | G35: =D35*F35 -> 6 | H35: =G35*Assumptions!$C$5 -> 1662
A36: 2 | B36: Data and coding | C36: Multan: data entry and coding | D36: =Regions!C7*Assumptions!$C$18 -> 4 | E36: days | F36: =Assumptions!$C$7 -> 15 | G36: =D36*F36 -> 60 | H36: =G36*Assumptions!$C$5 -> 16620 | I36: Function module entry and double check.
A37: 2 | B37: Fieldwork teams and travel | C37: Uch Sharif and Bahawalpur: enumerator days | D37: =Regions!K8 -> 14 | E37: enumerator days | F37: =Assumptions!$C$7 -> 15 | G37: =D37*F37 -> 210 | H37: =G37*Assumptions!$C$5 -> 58170 | I37: Two enumerators per visit outside Lahore; singly in Lahore, as in the Mittal budget.
A38: 2 | B38: Fieldwork teams and travel | C38: Uch Sharif and Bahawalpur: female enumerator days | D38: =Regions!L8 -> 4 | E38: days | F38: =Assumptions!$C$9 -> 15 | G38: =D38*F38 -> 60 | H38: =G38*Assumptions!$C$5 -> 16620 | I38: Women's spaces and women devotee interviews.
A39: 2 | B39: Fieldwork teams and travel | C39: Uch Sharif and Bahawalpur: field coordinator days | D39: =Regions!M8 -> 7 | E39: days | F39: =Assumptions!$C$8 -> 25 | G39: =D39*F39 -> 175 | H39: =G39*Assumptions!$C$5 -> 48475 | I39: Supervision of outstation teams.
A40: 2 | B40: Fieldwork teams and travel | C40: Uch Sharif and Bahawalpur: local transport | D40: =Regions!J8 -> 7 | E40: team field days | F40: =Assumptions!$C$22 -> 8 | G40: =D40*F40 -> 56 | H40: =G40*Assumptions!$C$5 -> 15512 | I40: Ride hail and rickshaw between sites.
A41: 2 | B41: Fieldwork teams and travel | C41: Uch Sharif and Bahawalpur: intercity fares | D41: =Regions!D8 -> 3 | E41: travellers | F41: =Regions!E8/Assumptions!$C$5 -> 22.238267 | G41: =D41*F41 -> 66.714801 | H41: =G41*Assumptions!$C$5 -> 18480 | I41: Round trip bus fare per traveller; see Regions.
...

Sheet Sources
A1: Sources consulted, 13 October 2026
A3: Figure | B3: Source | C3: URL
A4: PKR 277.11 per USD, 30 Sep 2026 | B4: ProPakistani | C4: https://propakistani.pk/2026/09/30/pkr-breaks-another-record-against-dollar/
A5: Punjab minimum wage PKR 40,000 a month from 1 Jul 2025 | B5: WageIndicator | C5: https://wageindicator.org/salary/minimum-wage/pakistan/168-punjab
A6: Daewoo Express fares from Lahore and Multan | B6: PK Buses fare list | C6: https://pkbuses.com/daewoo-express-ticket-price
A7: Lahore to Multan bus fares by operator | B7: Bookme | C7: https://bookme.pk/lahore-to-multan-bus-ticket-price
A8: Lahore to Karachi flights from PKR 17,240 | B8: Air Arabia | C8: https://flights.airarabia.com/en-pk/flights-from-lahore-to-karachi
A9: Multan hotel prices | B9: Champion Traveler | C9: https://championtraveler.com/price/cost-of-a-trip-to-multan-pk
A10: CZUR ET18 Pro at PKR 181,000 | B10: Paklap | C10: https://www.paklap.pk/czur-et18-scanner-price-reviews-pakistan.html
A11: Zoom H5studio at $349.99 | B11: Trew Audio | C11: https://www.trewaudio.com/product/zoom-h5studio-handy-recorder/
A12: Urdu transcription from $1.02 a minute | B12: GoTranscript | C12: https://gotranscript.com/transcribe-urdu-audio-to-english
A13: Enumerator, airfare, transport and archive rates | B13: Rauf Nawaz, Mittal Statement of Rationale and Budget | C13: Mittal Proposal folder, Google Drive
